Workbook

Sheet P
B1: DTHETA | C1: DBETA | D1: DALPHA | E1: DDELTA | F1: ALTRATE_212 | G1: COMPAIRSPEED_206 | H1: DIFFERENTIALPRESSURE_215 | I1: STATICAIRTEMP_213 | J1: STATICPRESSURE_217 | K1: STD ALTITUDE_203 | L1: TOTAL AIR TEMPERATURE_211 | M1: TRUE AIR SPEED_210 | N1: BAROALTITUDE_203 | O1: HEADING ANGLE_320 | P1: IAS_206 | Q1: LAT ACCELERATION_332 | R1: LONG ACCELERATION_331 | S1: NOR ACCELERATION_333 | T1: PITCH ANGLE_324 | U1: PITCH RATE_326 | V1: ROLL ANGLE_325 | W1: ROLL RATE_327 | X1: YAW RATE_330 | Y1: FADA_FFR_347 | Z1: FADA_NF_344 | AA1: FADA_NG_346 | AB1: FADA_TORQUE_336 | AC1: FADA_TI_211 | AD1: FADA_TGT_260 | AE1: SCDSA_NR_072 | AF1: GROUND_SPEED_DIU_336 | AG1: RADALT_MC1 | AH1: Time(sec) | AI1: HH:MM:SS | AJ1: TQ | AL1: Aft skid HT deduction | AM1: Tail guard wrt skid addition | AO1: Ct | AP1: Ct/Sigma
A2: vabs | B2: % | C2: % | D2: % | E2: % | F2: FT/MIN | G2: KNOTS | H2: hPa | I2: ?C | J2: hPa | K2: Feet | L2: ?C | M2: KNOTS | N2: Feet | O2: Deg | P2: KNOTS | Q2: g | R2: g | S2: g | T2: Deg | U2: Deg/Sec | V2: Deg | W2: Deg/Sec | X2: Deg/Sec | Y2: L/h | Z2: %Nf | AA2: %Ng | AB2: daNm | AC2: ?C | AD2: ?C | AE2: %Nr | AF2: Kts | AG2: Feet | AJ2: (%) | AL2: Feet | AM2: Feet | AR2: AUW | AS2: 2500 | AX2: 79.22 | AY2: 4 | AZ2: 40 | BA2: 10 | BB2: 0.02 | BC2: =AX2*0.8377 -> 66.362594
A3: "07/10/25 05:19:40,0589" | B3: 47.954 | C3: 48.872 | D3: 63.222 | E3: 50.046 | F3: -240 | G3: 23.875 | H3: 0.906 | I3: 25.75 | J3: 915.531 | K3: 2778 | L3: 25.75 | M3: 25.625 | N3: 2778 | O3: -90.794 | P3: 22.813 | Q3: -0.021 | R3: 0.115 | S3: -0.964 | T3: 0.372 | U3: 2.055 | V3: 2.462 | W3: 1.254 | X3: -2.896 | Y3: 185.063 | Z3: 100.047 | AA3: 88.813 | AB3: 61.055 | AC3: 28.813 | AD3: 712.875 | AE3: 100 | AF3: 24.5 | AG3: 23.375 | AH3: 0 | AI3: 0.22199074 | AJ3: =AB3*0.8377 -> 51.145773 | AL3: =(63.444*T3+1583.2)*0.00328083 -> 5.2716415 | AM3: =(-97.977*T3+1114.4)*0.00328083 -> 3.5365791 | AN3: =AE3*38.43/100 -> 38.43 | AO3: =(2*$AS$2*9.81*-S3)/($AS$5*$AS$7*((AN3*$AS$6)^2)) -> 0.0084463468 | AP3: =AO3/$AS$9 -> 0.10687701 | AR3: Ht(m) | AS3: =(AVERAGE(K3:K262))/3.2808 -> 845.46335 | AX3: 79.22 | AY3: 4 | AZ3: 40 | BA3: 10 | BB3: 0.04 | BC3: =AX3*0.8377 -> 66.362594
A4: "07/10/25 05:19:40,0973" | B4: 47.951 | C4: 49.49 | D4: 63.258 | E4: 50.226 | F4: -240 | G4: 23.875 | H4: 0.906 | I4: 25.75 | J4: 915.531 | K4: 2778 | L4: 25.75 | M4: 25.625 | N4: 2778 | O4: -90.883 | P4: 22.813 | Q4: -0.006 | R4: 0.122 | S4: -0.963 | T4: 0.446 | U4: 2.107 | V4: 2.494 | W4: 1.718 | X4: -2.831 | Y4: 185.063 | Z4: 100.055 | AA4: 88.789 | AB4: 61.008 | AC4: 28.773 | AD4: 712.625 | AE4: 100 | AF4: 24.5 | AG4: 23.375 | AH4: 0.038461538 | AI4: 0.22199074 | AJ4: =AB4*0.8377 -> 51.106402 | AL4: =(63.444*T4+1583.2)*0.00328083 -> 5.2870445 | AM4: =(-97.977*T4+1114.4)*0.00328083 -> 3.5127921 | AN4: =AE4*38.43/100 -> 38.43 | AO4: =(2*$AS$2*9.81*-S4)/($AS$5*$AS$7*((AN4*$AS$6)^2)) -> 0.008437585 | AP4: =AO4/$AS$9 -> 0.10676614 | AR4: T c | AS4: =AVERAGE(L3:L262) -> 25.794231 | AU4: 2099 | AX4: 79.25 | AY4: 4 | AZ4: 40 | BA4: 10 | BB4: 0.06 | BC4: =AX4*0.8377 -> 66.387725
A5: "07/10/25 05:19:40,1357" | B5: 47.943 | C5: 50.205 | D5: 63.301 | E5: 50.342 | F5: -240 | G5: 24.063 | H5: 0.938 | I5: 25.75 | J5: 915.563 | K5: 2778 | L5: 25.75 | M5: 25.813 | N5: 2778 | O5: -91.026 | P5: 22.813 | Q5: -0.004 | R5: 0.127 | S5: -0.972 | T5: 0.51 | U5: 2.07 | V5: 2.566 | W5: 1.82 | X5: -2.953 | Y5: 185.063 | Z5: 100.07 | AA5: 88.773 | AB5: 60.953 | AC5: 28.773 | AD5: 712.125 | AE5: 100 | AF5: 24.5 | AG5: 23.375 | AH5: 0.076923077 | AI5: 0.22199074 | AJ5: =AB5*0.8377 -> 51.060328 | AL5: =(63.444*T5+1583.2)*0.00328083 -> 5.300366 | AM5: =(-97.977*T5+1114.4)*0.00328083 -> 3.4922196 | AN5: =AE5*38.43/100 -> 38.43 | AO5: =(2*$AS$2*9.81*-S5)/($AS$5*$AS$7*((AN5*$AS$6)^2)) -> 0.008516441 | AP5: =AO5/$AS$9 -> 0.10776395 | AR5: ρ | AS5: =((101325*((1-(2.2558*AS3*(10^-5)))^5.2559))*0.00284/(AS4+273))*1.225 -> 1.0662143 | AU5: 328.5 | AX5: 79.25 | AY5: 4 | AZ5: 40 | BA5: 10 | BB5: 0.08 | BC5: =AX5*0.8377 -> 66.387725
A6: "07/10/25 05:19:40,1741" | B6: 47.935 | C6: 50.837 | D6: 63.386 | E6: 50.423 | F6: -224 | G6: 24.188 | H6: 0.938 | I6: 25.75 | J6: 915.563 | K6: 2778 | L6: 25.75 | M6: 25.938 | N6: 2778 | O6: -91.119 | P6: 22.813 | Q6: -0.014 | R6: 0.123 | S6: -0.993 | T6: 0.617 | U6: 2.057 | V6: 2.649 | W6: 1.667 | X6: -3.108 | Y6: 185.063 | Z6: 100.086 | AA6: 88.766 | AB6: 60.898 | AC6: 28.773 | AD6: 711.625 | AE6: 100.063 | AF6: 25.625 | AG6: 23.375 | AH6: 0.11538462 | AI6: 0.22199074 | AJ6: =AB6*0.8377 -> 51.014255 | AL6: =(63.444*T6+1583.2)*0.00328083 -> 5.322638 | AM6: =(-97.977*T6+1114.4)*0.00328083 -> 3.4578248 | AN6: =AE6*38.43/100 -> 38.454211 | AO6: =(2*$AS$2*9.81*-S6)/($AS$5*$AS$7*((AN6*$AS$6)^2)) -> 0.008689486 | AP6: =AO6/$AS$9 -> 0.1099536 | AR6: R | AS6: 5.8 | AU6: 170 | AX6: 79.26 | AY6: 4 | AZ6: 40 | BA6: 10 | BB6: 0.1 | BC6: =AX6*0.8377 -> 66.396102
A7: "07/10/25 05:19:40,2125" | B7: 47.935 | C7: 51.234 | D7: 63.477 | E7: 50.469 | F7: -224 | G7: 24.313 | H7: 0.938 | I7: 25.75 | J7: 915.563 | K7: 2778 | L7: 25.75 | M7: 26.063 | N7: 2776 | O7: -91.216 | P7: 23.438 | Q7: -0.027 | R7: 0.123 | S7: -1.026 | T7: 0.676 | U7: 1.848 | V7: 2.632 | W7: 1.37 | X7: -3.139 | Y7: 185.063 | Z7: 100.094 | AA7: 88.75 | AB7: 60.844 | AC7: 28.82 | AD7: 711.375 | AE7: 100.063 | AF7: 25.625 | AG7: 23.375 | AH7: 0.15384615 | AI7: 0.22199074 | AJ7: =AB7*0.8377 -> 50.969019 | AL7: =(63.444*T7+1583.2)*0.00328083 -> 5.3349188 | AM7: =(-97.977*T7+1114.4)*0.00328083 -> 3.4388595 | AN7: =AE7*38.43/100 -> 38.454211 | AO7: =(2*$AS$2*9.81*-S7)/($AS$5*$AS$7*((AN7*$AS$6)^2)) -> 0.0089782604 | AP7: =AO7/$AS$9 -> 0.11360765 | AR7: Area | AS7: =PI()*AS6*AS6 -> 105.68318 | AU7: =SUM(AU4:AU6) -> 2597.5 | AX7: 79.26 | AY7: 4 | AZ7: 40 | BA7: 10 | BB7: 0.12 | BC7: =AX7*0.8377 -> 66.396102
A8: "07/10/25 05:19:40,2509" | B8: 47.932 | C8: 51.284 | D8: 63.581 | E8: 50.504 | F8: -224 | G8: 24.313 | H8: 0.938 | I8: 25.75 | J8: 915.563 | K8: 2778 | L8: 26 | M8: 26.063 | N8: 2776 | O8: -91.356 | P8: 23.438 | Q8: -0.032 | R8: 0.112 | S8: -1.016 | T8: 0.762 | U8: 1.874 | V8: 2.679 | W8: 1.638 | X8: -3.132 | Y8: 185.063 | Z8: 100.094 | AA8: 88.727 | AB8: 60.789 | AC8: 28.82 | AD8: 711.063 | AE8: 100.063 | AF8: 25.625 | AG8: 23.375 | AH8: 0.19230769 | AI8: 0.22199074 | AJ8: =AB8*0.8377 -> 50.922945 | AL8: =(63.444*T8+1583.2)*0.00328083 -> 5.3528196 | AM8: =(-97.977*T8+1114.4)*0.00328083 -> 3.4112152 | AN8: =AE8*38.43/100 -> 38.454211 | AO8: =(2*$AS$2*9.81*-S8)/($AS$5*$AS$7*((AN8*$AS$6)^2)) -> 0.008890753 | AP8: =AO8/$AS$9 -> 0.11250036 | AR8: Ω | AS8: 38.43 | AU8: =AU7+204 -> 2801.5 | AX8: 79.26 | AY8: 4 | AZ8: 40 | BA8: 10 | BB8: 0.14 | BC8: =AX8*0.8377 -> 66.396102
A9: "07/10/25 05:19:40,2893" | B9: 47.905 | C9: 51.008 | D9: 63.666 | E9: 50.538 | F9: -224 | G9: 24.313 | H9: 0.938 | I9: 25.75 | J9: 915.563 | K9: 2778 | L9: 26 | M9: 26 | N9: 2776 | O9: -91.449 | P9: 23.438 | Q9: -0.037 | R9: 0.097 | S9: -0.999 | T9: 0.823 | U9: 1.678 | V9: 2.717 | W9: 1.728 | X9: -3.121 | Y9: 185.063 | Z9: 100.094 | AA9: 88.695 | AB9: 60.742 | AC9: 28.82 | AD9: 710.625 | AE9: 100.063 | AF9: 25.625 | AG9: 23.375 | AH9: 0.23076923 | AI9: 0.22199074 | AJ9: =AB9*0.8377 -> 50.883573 | AL9: =(63.444*T9+1583.2)*0.00328083 -> 5.3655167 | AM9: =(-97.977*T9+1114.4)*0.00328083 -> 3.391607 | AN9: =AE9*38.43/100 -> 38.454211 | AO9: =(2*$AS$2*9.81*-S9)/($AS$5*$AS$7*((AN9*$AS$6)^2)) -> 0.0087419904 | AP9: =AO9/$AS$9 -> 0.11061797 | AR9: Sigma | AS9: =4*0.36/(PI()*AS6) -> 0.079028661 | AX9: 79.26 | AY9: 4 | AZ9: 40 | BA9: 10 | BB9: 0.16 | BC9: =AX9*0.8377 -> 66.396102
A10: "07/10/25 05:19:40,3277" | B10: 47.844 | C10: 50.5 | D10: 63.763 | E10: 50.585 | F10: -208 | G10: 24.25 | H10: 0.938 | I10: 25.75 | J10: 915.563 | K10: 2777 | L10: 25.75 | M10: 26 | N10: 2776 | O10: -91.584 | P10: 23.438 | Q10: -0.046 | R10: 0.093 | S10: -0.988 | T10: 0.886 | U10: 1.49 | V10: 2.744 | W10: 0.042 | X10: -3.057 | Y10: 185.063 | Z10: 100.086 | AA10: 88.672 | AB10: 60.688 | AC10: 28.766 | AD10: 710.875 | AE10: 100.063 | AF10: 25.625 | AG10: 23.375 | AH10: 0.26923077 | AI10: 0.22199074 | AJ10: =AB10*0.8377 -> 50.838338 | AL10: =(63.444*T10+1583.2)*0.00328083 -> 5.3786301 | AM10: =(-97.977*T10+1114.4)*0.00328083 -> 3.3713559 | AN10: =AE10*38.43/100 -> 38.454211 | AO10: =(2*$AS$2*9.81*-S10)/($AS$5*$AS$7*((AN10*$AS$6)^2)) -> 0.0086457322 | AP10: =AO10/$AS$9 -> 0.10939996 | AX10: 79.26 | AY10: 4 | AZ10: 40 | BA10: 10 | BB10: 0.18 | BC10: =AX10*0.8377 -> 66.396102
A11: "07/10/25 05:19:40,3661" | B11: 47.756 | C11: 49.91 | D11: 63.818 | E11: 50.66 | F11: -208 | G11: 24.25 | H11: 0.938 | I11: 25.75 | J11: 915.563 | K11: 2778 | L11: 25.75 | M11: 26 | N11: 2778 | O11: -91.669 | P11: 24.063 | Q11: -0.054 | R11: 0.083 | S11: -0.968 | T11: 0.94 | U11: 1.201 | V11: 2.833 | W11: 0.224 | X11: -2.946 | Y11: 185.063 | Z11: 100.07 | AA11: 88.672 | AB11: 60.633 | AC11: 28.766 | AD11: 710.313 | AE11: 100.063 | AF11: 25.625 | AG11: 23.375 | AH11: 0.30769231 | AI11: 0.22199074 | AJ11: =AB11*0.8377 -> 50.792264 | AL11: =(63.444*T11+1583.2)*0.00328083 -> 5.3898701 | AM11: =(-97.977*T11+1114.4)*0.00328083 -> 3.3539978 | AN11: =AE11*38.43/100 -> 38.454211 | AO11: =(2*$AS$2*9.81*-S11)/($AS$5*$AS$7*((AN11*$AS$6)^2)) -> 0.0084707174 | AP11: =AO11/$AS$9 -> 0.10718538 | AX11: 79.26 | AY11: 4 | AZ11: 40 | BA11: 10 | BB11: 0.2 | BC11: =AX11*0.8377 -> 66.396102
A12: "07/10/25 05:19:40,4045" | B12: 47.66 | C12: 49.338 | D12: 63.818 | E12: 50.758 | F12: -192 | G12: 24.375 | H12: 0.938 | I12: 25.75 | J12: 915.563 | K12: 2778 | L12: 25.75 | M12: 26.125 | N12: 2778 | O12: -91.796 | P12: 24.063 | Q12: -0.065 | R12: 0.087 | S12: -0.954 | T12: 0.979 | U12: 0.888 | V12: 2.851 | W12: 0.853 | X12: -2.875 | Y12: 185.063 | Z12: 100.047 | AA12: 88.648 | AB12: 60.586 | AC12: 28.766 | AD12: 710.063 | AE12: 100 | AF12: 25.625 | AG12: 23.25 | AH12: 0.34615385 | AI12: 0.22199074 | AJ12: =AB12*0.8377 -> 50.752892 | AL12: =(63.444*T12+1583.2)*0.00328083 -> 5.3979879 | AM12: =(-97.977*T12+1114.4)*0.00328083 -> 3.3414614 | AN12: =AE12*38.43/100 -> 38.43 | AO12: =(2*$AS$2*9.81*-S12)/($AS$5*$AS$7*((AN12*$AS$6)^2)) -> 0.0083587291 | AP12: =AO12/$AS$9 -> 0.10576832 | AX12: 79.27 | AY12: 4 | AZ12: 40 | BA12: 10 | BB12: 0.22 | BC12: =AX12*0.8377 -> 66.404479
A13: "07/10/25 05:19:40,4429" | B13: 47.573 | C13: 48.844 | D13: 63.745 | E13: 50.903 | F13: -192 | G13: 24.375 | H13: 0.938 | I13: 25.75 | J13: 915.563 | K13: 2778 | L13: 25.75 | M13: 26.125 | N13: 2778 | O13: -91.875 | P13: 24.063 | Q13: -0.058 | R13: 0.087 | S13: -0.911 | T13: 1.013 | U13: 0.722 | V13: 3 | W13: 1.337 | X13: -2.706 | Y13: 185.063 | Z13: 100.031 | AA13: 88.633 | AB13: 60.547 | AC13: 28.797 | AD13: 709.813 | AE13: 100 | AF13: 25.625 | AG13: 23.25 | AH13: 0.38461538 | AI13: 0.22199074 | AJ13: =AB13*0.8377 -> 50.720222 | AL13: =(63.444*T13+1583.2)*0.00328083 -> 5.405065 | AM13: =(-97.977*T13+1114.4)*0.00328083 -> 3.3305323 | AN13: =AE13*38.43/100 -> 38.43 | AO13: =(2*$AS$2*9.81*-S13)/($AS$5*$AS$7*((AN13*$AS$6)^2)) -> 0.007981973 | AP13: =AO13/$AS$9 -> 0.10100099 | AX13: 79.27 | AY13: 4 | AZ13: 40 | BA13: 10 | BB13: 0.24 | BC13: =AX13*0.8377 -> 66.404479
A14: "07/10/25 05:19:40,4813" | B14: 47.458 | C14: 48.36 | D14: 63.569 | E14: 51.088 | F14: -192 | G14: 24.313 | H14: 0.938 | I14: 25.75 | J14: 915.531 | K14: 2778 | L14: 25.75 | M14: 26.063 | N14: 2778 | O14: -92 | P14: 24.063 | Q14: -0.059 | R14: 0.088 | S14: -0.915 | T14: 1.037 | U14: 0.393 | V14: 3.019 | W14: 1.224 | X14: -2.643 | Y14: 185.063 | Z14: 100.008 | AA14: 88.625 | AB14: 60.516 | AC14: 28.797 | AD14: 709 | AE14: 100 | AF14: 25.625 | AG14: 23.25 | AH14: 0.42307692 | AI14: 0.22199074 | AJ14: =AB14*0.8377 -> 50.694253 | AL14: =(63.444*T14+1583.2)*0.00328083 -> 5.4100605 | AM14: =(-97.977*T14+1114.4)*0.00328083 -> 3.3228176 | AN14: =AE14*38.43/100 -> 38.43 | AO14: =(2*$AS$2*9.81*-S14)/($AS$5*$AS$7*((AN14*$AS$6)^2)) -> 0.00801702 | AP14: =AO14/$AS$9 -> 0.10144446 | AX14: 79.27 | AY14: 4 | AZ14: 40 | BA14: 10 | BB14: 0.26 | BC14: =AX14*0.8377 -> 66.404479
A15: "07/10/25 05:19:40,5197" | B15: 47.355 | C15: 47.811 | D15: 63.222 | E15: 51.314 | F15: -192 | G15: 24.188 | H15: 0.938 | I15: 25.75 | J15: 915.563 | K15: 2778 | L15: 25.75 | M15: 25.938 | N15: 2778 | O15: -92.076 | P15: 24.063 | Q15: -0.063 | R15: 0.09 | S15: -0.922 | T15: 1.04 | U15: 0.185 | V15: 3.156 | W15: 1.342 | X15: -2.63 | Y15: 185.063 | Z15: 100 | AA15: 88.617 | AB15: 60.492 | AC15: 28.813 | AD15: 708.813 | AE15: 100 | AF15: 25.625 | AG15: 23.25 | AH15: 0.46153846 | AI15: 0.22199074 | AJ15: =AB15*0.8377 -> 50.674148 | AL15: =(63.444*T15+1583.2)*0.00328083 -> 5.410685 | AM15: =(-97.977*T15+1114.4)*0.00328083 -> 3.3218532 | AN15: =AE15*38.43/100 -> 38.43 | AO15: =(2*$AS$2*9.81*-S15)/($AS$5*$AS$7*((AN15*$AS$6)^2)) -> 0.0080783524 | AP15: =AO15/$AS$9 -> 0.10222054 | AX15: 79.27 | AY15: 4 | AZ15: 40 | BA15: 10 | BB15: 0.28 | BC15: =AX15*0.8377 -> 66.404479
A16: "07/10/25 05:19:40,5581" | B16: 47.26 | C16: 47.193 | D16: 62.711 | E16: 51.552 | F16: -192 | G16: 24.063 | H16: 0.938 | I16: 25.75 | J16: 915.563 | K16: 2778 | L16: 25.75 | M16: 25.813 | N16: 2776 | O16: -92.19 | P16: 24.25 | Q16: -0.047 | R16: 0.086 | S16: -0.898 | T16: 1.043 | U16: -0.02 | V16: 3.146 | W16: 1.38 | X16: -2.483 | Y16: 185.063 | Z16: 100 | AA16: 88.609 | AB16: 60.461 | AC16: 28.813 | AD16: 708.5 | AE16: 99.938 | AF16: 25.625 | AG16: 23.25 | AH16: 0.5 | AI16: 0.22199074 | AJ16: =AB16*0.8377 -> 50.64818 | AL16: =(63.444*T16+1583.2)*0.00328083 -> 5.4113094 | AM16: =(-97.977*T16+1114.4)*0.00328083 -> 3.3208889 | AN16: =AE16*38.43/100 -> 38.406173 | AO16: =(2*$AS$2*9.81*-S16)/($AS$5*$AS$7*((AN16*$AS$6)^2)) -> 0.0078778354 | AP16: =AO16/$AS$9 -> 0.099683271 | AX16: 79.28 | AY16: 4 | AZ16: 40 | BA16: 10 | BB16: 0.3 | BC16: =AX16*0.8377 -> 66.412856
A17: "07/10/25 05:19:40,5965" | B17: 47.195 | C17: 46.588 | D17: 62.109 | E17: 51.789 | F17: -192 | G17: 24.063 | H17: 0.938 | I17: 25.75 | J17: 915.563 | K17: 2778 | L17: 25.75 | M17: 25.813 | N17: 2776 | O17: -92.266 | P17: 24.25 | Q17: -0.053 | R17: 0.104 | S17: -0.908 | T17: 1.048 | U17: -0.103 | V17: 3.193 | W17: 1.597 | X17: -2.423 | Y17: 185.063 | Z17: 100 | AA17: 88.602 | AB17: 60.422 | AC17: 28.813 | AD17: 708.063 | AE17: 99.938 | AF17: 25.625 | AG17: 23.125 | AH17: 0.53846154 | AI17: 0.22199074 | AJ17: =AB17*0.8377 -> 50.615509 | AL17: =(63.444*T17+1583.2)*0.00328083 -> 5.4123502 | AM17: =(-97.977*T17+1114.4)*0.00328083 -> 3.3192817 | AN17: =AE17*38.43/100 -> 38.406173 | AO17: =(2*$AS$2*9.81*-S17)/($AS$5*$AS$7*((AN17*$AS$6)^2)) -> 0.0079655619 | AP17: =AO17/$AS$9 -> 0.10079333 | AX17: 79.28 | AY17: 4 | AZ17: 40 | BA17: 10 | BB17: 0.32 | BC17: =AX17*0.8377 -> 66.412856
A18: "07/10/25 05:19:40,6349" | B18: 47.145 | C18: 46.109 | D18: 61.488 | E18: 52.003 | F18: -176 | G18: 24.125 | H18: 0.938 | I18: 25.75 | J18: 915.563 | K18: 2778 | L18: 25.75 | M18: 25.875 | N18: 2776 | O18: -92.339 | P18: 24.25 | Q18: -0.048 | R18: 0.106 | S18: -0.894 | T18: 1.053 | U18: -0.175 | V18: 3.246 | W18: 1.471 | X18: -2.442 | Y18: 185.063 | Z18: 100 | AA18: 88.586 | AB18: 60.383 | AC18: 28.813 | AD18: 708.063 | AE18: 100 | AF18: 25.625 | AG18: 23.125 | AH18: 0.57692308 | AI18: 0.22199074 | AJ18: =AB18*0.8377 -> 50.582839 | AL18: =(63.444*T18+1583.2)*0.00328083 -> 5.4133909 | AM18: =(-97.977*T18+1114.4)*0.00328083 -> 3.3176744 | AN18: =AE18*38.43/100 -> 38.43 | AO18: =(2*$AS$2*9.81*-S18)/($AS$5*$AS$7*((AN18*$AS$6)^2)) -> 0.0078330229 | AP18: =AO18/$AS$9 -> 0.099116229 | AX18: 79.28 | AY18: 4 | AZ18: 40 | BA18: 10 | BB18: 0.34 | BC18: =AX18*0.8377 -> 66.412856
A19: "07/10/25 05:19:40,6733" | B19: 47.103 | C19: 45.827 | D19: 60.941 | E19: 52.188 | F19: -176 | G19: 24.063 | H19: 0.938 | I19: 25.75 | J19: 915.563 | K19: 2777 | L19: 25.75 | M19: 25.813 | N19: 2776 | O19: -92.447 | P19: 24.25 | Q19: -0.037 | R19: 0.098 | S19: -0.906 | T19: 1.057 | U19: -0.154 | V19: 3.343 | W19: 1.627 | X19: -2.367 | Y19: 185.063 | Z19: 100.008 | AA19: 88.578 | AB19: 60.344 | AC19: 28.813 | AD19: 708.063 | AE19: 100 | AF19: 26.375 | AG19: 23.125 | AH19: 0.61538462 | AI19: 0.22199074 | AJ19: =AB19*0.8377 -> 50.550169 | AL19: =(63.444*T19+1583.2)*0.00328083 -> 5.4142235 | AM19: =(-97.977*T19+1114.4)*0.00328083 -> 3.3163887 | AN19: =AE19*38.43/100 -> 38.43 | AO19: =(2*$AS$2*9.81*-S19)/($AS$5*$AS$7*((AN19*$AS$6)^2)) -> 0.0079381641 | AP19: =AO19/$AS$9 -> 0.10044665 | AX19: 79.28 | AY19: 4 | AZ19: 40 | BA19: 10 | BB19: 0.36 | BC19: =AX19*0.8377 -> 66.412856
A20: "07/10/25 05:19:40,7117" | B20: 47.088 | C20: 45.721 | D20: 60.527 | E20: 52.345 | F20: -176 | G20: 24.125 | H20: 0.938 | I20: 25.75 | J20: 915.563 | K20: 2777 | L20: 25.75 | M20: 25.813 | N20: 2776 | O20: -92.512 | P20: 24.25 | Q20: -0.023 | R20: 0.11 | S20: -0.938 | T20: 1.063 | U20: -0.013 | V20: 3.352 | W20: 1.688 | X20: -2.303 | Y20: 181.938 | Z20: 100 | AA20: 88.57 | AB20: 60.289 | AC20: 28.805 | AD20: 707.75 | AE20: 100 | AF20: 26.375 | AG20: 23.125 | AH20: 0.65384615 | AI20: 0.22199074 | AJ20: =AB20*0.8377 -> 50.504095 | AL20: =(63.444*T20+1583.2)*0.00328083 -> 5.4154724 | AM20: =(-97.977*T20+1114.4)*0.00328083 -> 3.31446 | AN20: =AE20*38.43/100 -> 38.43 | AO20: =(2*$AS$2*9.81*-S20)/($AS$5*$AS$7*((AN20*$AS$6)^2)) -> 0.0082185408 | AP20: =AO20/$AS$9 -> 0.10399443 | AX20: 79.27 | AY20: 4 | AZ20: 40 | BA20: 10 | BB20: 0.38 | BC20: =AX20*0.8377 -> 66.404479
A21: "07/10/25 05:19:40,7501" | B21: 47.088 | C21: 45.749 | D21: 60.326 | E21: 52.478 | F21: -160 | G21: 24 | H21: 0.938 | I21: 25.75 | J21: 915.563 | K21: 2777 | L21: 26 | M21: 25.813 | N21: 2778 | O21: -92.601 | P21: 24.313 | Q21: -0.032 | R21: 0.107 | S21: -0.953 | T21: 1.074 | U21: 0.063 | V21: 3.463 | W21: 2.231 | X21: -2.236 | Y21: 181.938 | Z21: 100.008 | AA21: 88.539 | AB21: 60.227 | AC21: 28.805 | AD21: 707.75 | AE21: 99.938 | AF21: 26.375 | AG21: 23.125 | AH21: 0.69230769 | AI21: 0.22199074 | AJ21: =AB21*0.8377 -> 50.452158 | AL21: =(63.444*T21+1583.2)*0.00328083 -> 5.4177621 | AM21: =(-97.977*T21+1114.4)*0.00328083 -> 3.3109241 | AN21: =AE21*38.43/100 -> 38.406173 | AO21: =(2*$AS$2*9.81*-S21)/($AS$5*$AS$7*((AN21*$AS$6)^2)) -> 0.0083603309 | AP21: =AO21/$AS$9 -> 0.10578859 | AX21: 79.27 | AY21: 4 | AZ21: 40 | BA21: 10 | BB21: 0.4 | BC21: =AX21*0.8377 -> 66.404479
... A523: "07/10/25 05:20:00,0269" | B523: 29.983 | C523: 12.291 | D523: 37.959 | E523: 8.991 | F523: 112 | G523: 22.75 | H523: 0.813 | I523: 25.75 | J523: 915.938 | K523: 2767 | L523: 25.75 | M523: 24.375 | N523: 2766 | O523: -93.548 | P523: 23.75 | Q523: 0.089 | R523: -0.214 | S523: -0.84 | T523: 0.101 | U523: 5.118 | V523: -0.869 | W523: -1.677 | X523: -1.837 | Y523: 0 | Z523: 41.266 | AA523: 24.727 | AB523: 0 | AC523: 28.258 | AD523: 267.75 | AE523: 43.375 | AF523: 25.25 | AG523: 0 | AH523: 20 | AI523: 0.22222222 | AJ523: =AB523*0.8377 -> 0 | AL523: =(63.444*T523+1583.2)*0.00328083 -> 5.2152331 | AM523: =(-97.977*T523+1114.4)*0.00328083 -> 3.6236909 | AN523: =AE523*38.43/100 -> 16.669012 | AO523: =(2*$AS$2*9.81*-S523)/($AS$5*$AS$7*((AN523*$AS$6)^2)) -> 0.0391194 | AP523: =AO523/$AS$9 -> 0.49500269 | AX523: 7.41 | AY523: 4 | AZ523: 40 | BA523: 20 | BB523: 10.44 | BC523: =AX523*0.8377 -> 6.207357
A524: "07/10/25 05:20:00,0653" | B524: 30.044 | C524: 12.263 | D524: 37.917 | E524: 9.153 | F524: 112 | G524: 22.625 | H524: 0.813 | I524: 25.75 | J524: 915.938 | K524: 2766 | L524: 25.75 | M524: 24.25 | N524: 2766 | O524: -93.594 | P524: 23.688 | Q524: -0.093 | R524: -0.236 | S524: -0.794 | T524: 0.429 | U524: 7.259 | V524: -0.917 | W524: -2.292 | X524: -2.149 | Y524: 0 | Z524: 41.188 | AA524: 24.656 | AB524: 0 | AC524: 28.258 | AD524: 266.938 | AE524: 43.375 | AF524: 25.25 | AG524: 0 | AH524: 20.038462 | AI524: 0.22222222 | AJ524: =AB524*0.8377 -> 0 | AL524: =(63.444*T524+1583.2)*0.00328083 -> 5.283506 | AM524: =(-97.977*T524+1114.4)*0.00328083 -> 3.5182567 | AN524: =AE524*38.43/100 -> 16.669012 | AO524: =(2*$AS$2*9.81*-S524)/($AS$5*$AS$7*((AN524*$AS$6)^2)) -> 0.036977147 | AP524: =AO524/$AS$9 -> 0.4678954
A525: "07/10/25 05:20:00,1037" | B525: 30.025 | C525: 12.203 | D525: 37.971 | E525: 9.234 | F525: 112 | G525: 22.563 | H525: 0.813 | I525: 25.75 | J525: 915.938 | K525: 2767 | L525: 25.75 | M525: 24.188 | N525: 2766 | O525: -93.634 | P525: 23.688 | Q525: -0.044 | R525: -0.139 | S525: -0.438 | T525: 0.774 | U525: 10.399 | V525: -0.956 | W525: -0.239 | X525: -1.576 | Y525: 0 | Z525: 41.117 | AA525: 24.594 | AB525: 0 | AC525: 28.328 | AD525: 267.188 | AE525: 43.25 | AF525: 25.25 | AG525: 0 | AH525: 20.076923 | AI525: 0.22222222 | AJ525: =AB525*0.8377 -> 0 | AL525: =(63.444*T525+1583.2)*0.00328083 -> 5.3553174 | AM525: =(-97.977*T525+1114.4)*0.00328083 -> 3.4073578 | AN525: =AE525*38.43/100 -> 16.620975 | AO525: =(2*$AS$2*9.81*-S525)/($AS$5*$AS$7*((AN525*$AS$6)^2)) -> 0.020516051 | AP525: =AO525/$AS$9 -> 0.25960266
A526: "07/10/25 05:20:00,1421" | B526: 29.666 | C526: 12.291 | D526: 38.002 | E526: 9.234 | F526: 112 | G526: 22.563 | H526: 0.813 | I526: 25.75 | J526: 915.938 | K526: 2767 | L526: 25.75 | M526: 24.188 | N526: 2766 | O526: -93.693 | P526: 23.688 | Q526: -0.017 | R526: -0.098 | S526: -0.568 | T526: 1.287 | U526: 11.575 | V526: -0.892 | W526: 1.537 | X526: -1.122 | Y526: 0 | Z526: 41.039 | AA526: 24.523 | AB526: 0 | AC526: 28.328 | AD526: 267.438 | AE526: 43.25 | AF526: 25.25 | AG526: 0 | AH526: 20.115385 | AI526: 0.22222222 | AJ526: =AB526*0.8377 -> 0 | AL526: =(63.444*T526+1583.2)*0.00328083 -> 5.4620978 | AM526: =(-97.977*T526+1114.4)*0.00328083 -> 3.2424561 | AN526: =AE526*38.43/100 -> 16.620975 | AO526: =(2*$AS$2*9.81*-S526)/($AS$5*$AS$7*((AN526*$AS$6)^2)) -> 0.026605289 | AP526: =AO526/$AS$9 -> 0.33665368
A527: "07/10/25 05:20:00,1805" | B527: 28.773 | C527: 12.554 | D527: 37.886 | E527: 9.24 | F527: 112 | G527: 22.375 | H527: 0.813 | I527: 25.75 | J527: 915.906 | K527: 2767 | L527: 25.75 | M527: 24 | N527: 2766 | O527: -93.73 | P527: 23.688 | Q527: 0.057 | R527: -0.224 | S527: -1.056 | T527: 1.59 | U527: 9.649 | V527: -0.842 | W527: 2.361 | X527: -1.109 | Y527: 0 | Z527: 40.969 | AA527: 24.461 | AB527: 0 | AC527: 28.328 | AD527: 267.188 | AE527: 43.125 | AF527: 23.125 | AG527: 0 | AH527: 20.153846 | AI527: 0.22222222 | AJ527: =AB527*0.8377 -> 0 | AL527: =(63.444*T527+1583.2)*0.00328083 -> 5.5251669 | AM527: =(-97.977*T527+1114.4)*0.00328083 -> 3.145058 | AN527: =AE527*38.43/100 -> 16.572938 | AO527: =(2*$AS$2*9.81*-S527)/($AS$5*$AS$7*((AN527*$AS$6)^2)) -> 0.049750515 | AP527: =AO527/$AS$9 -> 0.62952496
A528: "07/10/25 05:20:00,2189" | B528: 27.562 | C528: 12.886 | D528: 37.546 | E528: 9.292 | F528: 112 | G528: 22.188 | H528: 0.781 | I528: 25.5 | J528: 915.938 | K528: 2767 | L528: 25.75 | M528: 23.813 | N528: 2766 | O528: -93.786 | P528: 23.688 | Q528: 0.058 | R528: -0.306 | S528: -1.251 | T528: 1.865 | U528: 6.458 | V528: -0.677 | W528: 3.507 | X528: -1.087 | Y528: 0 | Z528: 40.898 | AA528: 24.391 | AB528: 0 | AC528: 28.305 | AD528: 267.063 | AE528: 43.125 | AF528: 23.125 | AG528: 0 | AH528: 20.192308 | AI528: 0.22222222 | AJ528: =AB528*0.8377 -> 0 | AL528: =(63.444*T528+1583.2)*0.00328083 -> 5.5824079 | AM528: =(-97.977*T528+1114.4)*0.00328083 -> 3.0566604 | AN528: =AE528*38.43/100 -> 16.572938 | AO528: =(2*$AS$2*9.81*-S528)/($AS$5*$AS$7*((AN528*$AS$6)^2)) -> 0.058937399 | AP528: =AO528/$AS$9 -> 0.74577246
A529: "07/10/25 05:20:00,2573" | B529: 26.44 | C529: 13.232 | D529: 37.248 | E529: 9.35 | F529: 112 | G529: 22.063 | H529: 0.781 | I529: 25.5 | J529: 915.938 | K529: 2767 | L529: 25.75 | M529: 23.625 | N529: 2766 | O529: -93.83 | P529: 22.75 | Q529: 0.061 | R529: -0.428 | S529: -1.391 | T529: 1.905 | U529: 2.744 | V529: -0.742 | W529: 1.01 | X529: -1.117 | Y529: 0 | Z529: 40.82 | AA529: 24.32 | AB529: 0 | AC529: 28.305 | AD529: 266.813 | AE529: 43.063 | AF529: 23.125 | AG529: 0 | AH529: 20.230769 | AI529: 0.22222222 | AJ529: =AB529*0.8377 -> 0 | AL529: =(63.444*T529+1583.2)*0.00328083 -> 5.5907339 | AM529: =(-97.977*T529+1114.4)*0.00328083 -> 3.0438025 | AN529: =AE529*38.43/100 -> 16.549111 | AO529: =(2*$AS$2*9.81*-S529)/($AS$5*$AS$7*((AN529*$AS$6)^2)) -> 0.06572195 | AP529: =AO529/$AS$9 -> 0.83162171
A530: "07/10/25 05:20:00,2957" | B530: 25.734 | C530: 13.504 | D530: 37.199 | E530: 9.413 | F530: 96 | G530: 22.063 | H530: 0.781 | I530: 25.5 | J530: 915.938 | K530: 2767 | L530: 25.75 | M530: 23.625 | N530: 2766 | O530: -93.895 | P530: 22.75 | Q530: 0.04 | R530: -0.449 | S530: -1.55 | T530: 1.712 | U530: -2.352 | V530: -0.786 | W530: -2.576 | X530: -1.268 | Y530: 0 | Z530: 40.742 | AA530: 24.258 | AB530: 0 | AC530: 28.336 | AD530: 266.375 | AE530: 43.063 | AF530: 23.125 | AG530: 0 | AH530: 20.269231 | AI530: 0.22222222 | AJ530: =AB530*0.8377 -> 0 | AL530: =(63.444*T530+1583.2)*0.00328083 -> 5.5505611 | AM530: =(-97.977*T530+1114.4)*0.00328083 -> 3.1058416 | AN530: =AE530*38.43/100 -> 16.549111 | AO530: =(2*$AS$2*9.81*-S530)/($AS$5*$AS$7*((AN530*$AS$6)^2)) -> 0.07323438 | AP530: =AO530/$AS$9 -> 0.92668127
A531: "07/10/25 05:20:00,3341" | B531: 25.547 | C531: 13.495 | D531: 37.345 | E531: 9.454 | F531: 96 | G531: 21.875 | H531: 0.75 | I531: 25.75 | J531: 915.938 | K531: 2767 | L531: 25.75 | M531: 23.438 | N531: 2766 | O531: -93.915 | P531: 22.75 | Q531: -0.144 | R531: -0.286 | S531: -1.363 | T531: 1.43 | U531: -7.854 | V531: -0.976 | W531: -3.938 | X531: -1.497 | Y531: 0 | Z531: 40.664 | AA531: 24.195 | AB531: 0 | AC531: 28.336 | AD531: 266.063 | AE531: 42.938 | AF531: 23.125 | AG531: 0 | AH531: 20.307692 | AI531: 0.22222222 | AJ531: =AB531*0.8377 -> 0 | AL531: =(63.444*T531+1583.2)*0.00328083 -> 5.4918631 | AM531: =(-97.977*T531+1114.4)*0.00328083 -> 3.1964893 | AN531: =AE531*38.43/100 -> 16.501073 | AO531: =(2*$AS$2*9.81*-S531)/($AS$5*$AS$7*((AN531*$AS$6)^2)) -> 0.064774506 | AP531: =AO531/$AS$9 -> 0.81963309
A532: "07/10/25 05:20:00,3725" | B532: 25.764 | C532: 13.116 | D532: 37.606 | E532: 9.442 | F532: 96 | G532: 21.625 | H532: 0.75 | I532: 25.75 | J532: 915.938 | K532: 2767 | L532: 25.75 | M532: 23.188 | N532: 2766 | O532: -93.943 | P532: 22.75 | Q532: -0.032 | R532: -0.346 | S532: -1.199 | T532: 0.884 | U532: -11.422 | V532: -0.979 | W532: -1.523 | X532: -1.056 | Y532: 0 | Z532: 40.594 | AA532: 24.133 | AB532: 0 | AC532: 28.336 | AD532: 266.125 | AE532: 42.938 | AF532: 23.125 | AG532: 0 | AH532: 20.346154 | AI532: 0.22222222 | AJ532: =AB532*0.8377 -> 0 | AL532: =(63.444*T532+1583.2)*0.00328083 -> 5.3782138 | AM532: =(-97.977*T532+1114.4)*0.00328083 -> 3.3719988 | AN532: =AE532*38.43/100 -> 16.501073 | AO532: =(2*$AS$2*9.81*-S532)/($AS$5*$AS$7*((AN532*$AS$6)^2)) -> 0.056980655 | AP532: =AO532/$AS$9 -> 0.72101253
A533: "07/10/25 05:20:00,4109" | B533: 26.047 | C533: 12.447 | D533: 37.892 | E533: 9.373 | F533: 96 | G533: 21.375 | H533: 0.719 | I533: 25.75 | J533: 915.938 | K533: 2767 | L533: 25.75 | M533: 22.875 | N533: 2766 | O533: -93.955 | P533: 22.75 | Q533: 0.01 | R533: -0.243 | S533: -0.871 | T533: 0.497 | U533: -12.306 | V533: -0.807 | W533: 2.463 | X533: -0.735 | Y533: 0 | Z533: 40.516 | AA533: 24.063 | AB533: 0 | AC533: 28.336 | AD533: 266.313 | AE533: 42.875 | AF533: 23.125 | AG533: 0 | AH533: 20.384615 | AI533: 0.22222222 | AJ533: =AB533*0.8377 -> 0 | AL533: =(63.444*T533+1583.2)*0.00328083 -> 5.2976601 | AM533: =(-97.977*T533+1114.4)*0.00328083 -> 3.4963983 | AN533: =AE533*38.43/100 -> 16.476862 | AO533: =(2*$AS$2*9.81*-S533)/($AS$5*$AS$7*((AN533*$AS$6)^2)) -> 0.041514687 | AP533: =AO533/$AS$9 -> 0.52531178
A534: "07/10/25 05:20:00,4493" | B534: 26.119 | C534: 11.737 | D534: 38.026 | E534: 9.263 | F534: 96 | G534: 21.188 | H534: 0.719 | I534: 25.5 | J534: 915.938 | K534: 2767 | L534: 25.75 | M534: 22.875 | N534: 2766 | O534: -93.986 | P534: 22.375 | Q534: 0.029 | R534: -0.159 | S534: -0.671 | T534: 0.057 | U534: -10.522 | V534: -0.735 | W534: 2.998 | X534: -0.604 | Y534: 0 | Z534: 40.445 | AA534: 23.992 | AB534: 0 | AC534: 28.336 | AD534: 266.375 | AE534: 42.875 | AF534: 23.125 | AG534: 0 | AH534: 20.423077 | AI534: 0.22222222 | AJ534: =AB534*0.8377 -> 0 | AL534: =(63.444*T534+1583.2)*0.00328083 -> 5.2060745 | AM534: =(-97.977*T534+1114.4)*0.00328083 -> 3.6378345 | AN534: =AE534*38.43/100 -> 16.476862 | AO534: =(2*$AS$2*9.81*-S534)/($AS$5*$AS$7*((AN534*$AS$6)^2)) -> 0.031982038 | AP534: =AO534/$AS$9 -> 0.4046891
A535: "07/10/25 05:20:00,4877" | B535: 25.967 | C535: 11.253 | D535: 37.965 | E535: 9.193 | F535: 96 | G535: 21.188 | H535: 0.719 | I535: 25.5 | J535: 915.906 | K535: 2767 | L535: 25.75 | M535: 22.688 | N535: 2766 | O535: -94.009 | P535: 22.375 | Q535: 0.045 | R535: -0.185 | S535: -0.685 | T535: -0.161 | U535: -7.532 | V535: -0.771 | W535: -0.247 | X535: -0.647 | Y535: 0 | Z535: 40.367 | AA535: 23.922 | AB535: 0 | AC535: 28.336 | AD535: 265.813 | AE535: 42.75 | AF535: 23.125 | AG535: 0 | AH535: 20.461538 | AI535: 0.22222222 | AJ535: =AB535*0.8377 -> 0 | AL535: =(63.444*T535+1583.2)*0.00328083 -> 5.1606981 | AM535: =(-97.977*T535+1114.4)*0.00328083 -> 3.7079097 | AN535: =AE535*38.43/100 -> 16.428825 | AO535: =(2*$AS$2*9.81*-S535)/($AS$5*$AS$7*((AN535*$AS$6)^2)) -> 0.032840534 | AP535: =AO535/$AS$9 -> 0.4155522
... A783: "07/10/25 05:20:10,0109" | B783: 0.134 | C783: 22.398 | D783: 31.371 | E783: 6.988 | F783: 0 | G783: 15.625 | H783: 0.375 | I783: 25.75 | J783: 915.781 | K783: 2771 | L783: 25.75 | M783: 16.75 | N783: 2772 | O783: -94.666 | P783: 15.75 | Q783: 0.021 | R783: 0.016 | S783: -0.97 | T783: 1.348 | U783: -0.01 | V783: -1.167 | W783: 0.01 | X783: 0.091 | Y783: 0 | Z783: 27.414 | AA783: 14.227 | AB783: 0 | AC783: 28.695 | AD783: 258.813 | AE783: 32.813 | AF783: 0 | AG783: 0 | AH783: 30 | AI783: 0.22233796 | AJ783: =AB783*0.8377 -> 0 | AL783: =(63.444*T783+1583.2)*0.00328083 -> 5.4747949 | AM783: =(-97.977*T783+1114.4)*0.00328083 -> 3.2228479 | AN783: =AE783*38.43/100 -> 12.610036 | AO783: =(2*$AS$2*9.81*-S783)/($AS$5*$AS$7*((AN783*$AS$6)^2)) -> 0.078935385 | AP783: =AO783/$AS$9 -> 0.99881972
AX785: 0 | AY785: 4 | AZ785: 40 | BA785: 25 | BB785: 15.68 | BC785: =AX785*0.8377 -> 0
AX786: 0 | AY786: 4 | AZ786: 40 | BA786: 25 | BB786: 15.7 | BC786: =AX786*0.8377 -> 0
AX787: 0 | AY787: 4 | AZ787: 40 | BA787: 25 | BB787: 15.72 | BC787: =AX787*0.8377 -> 0
AX788: 0 | AY788: 4 | AZ788: 40 | BA788: 25 | BB788: 15.74 | BC788: =AX788*0.8377 -> 0
AX789: 0 | AY789: 4 | AZ789: 40 | BA789: 25 | BB789: 15.76 | BC789: =AX789*0.8377 -> 0
...

Sheet D
A1: Time | G1: Gd Spd | H1: Ht | I1: Vz | J1: X distance moved | N1: GS | O1: Vz | P1: Height | Q1: HAGL | S1: Concrete | T1: 889.5 | V1: Horizontal distance moved
G2: knots | H2: m | I2: sec | J2: m | N2: knot | O2: fpm | P2: Ft | Q2: ft | R2: Aft Skid | S2: Tail guard | V2: ft.
A3: 51938.5 | G3: 25.336 | H3: 896.1028 | I3: -0.0778 | J3: 0 | M3: 0.1 | N3: =G3 -> 25.336 | O3: =I3*196.8504 -> -15.314961 | P3: =H3*3.28083 -> 2939.9609 | Q3: =(H3-T$1)*3.28083+5.38 -> 27.042664 | R3: =$Q3-LOOKUP($M3,P!$AH$3:$AH$523,P!$AL$3:$AL$523) -> 21.742298 | S3: =R3+LOOKUP($M3,P!$AH$3:$AH$523,P!$AM$3:$AM$523) -> 25.234518 | T3: 0 | V3: {=J3:J303} -> 0
A4: 51938.6 | G4: 25.478 | H4: 896.0983 | I4: -0.042 | J4: 2.0493714 | M4: 0.2 | N4: =G4 -> 25.478 | O4: =I4*196.8504 -> -8.2677168 | P4: =H4*3.28083 -> 2939.9462 | Q4: =(H4-T$1)*3.28083+5.38 -> 27.027901 | R4: =$Q4-LOOKUP($M4,P!$AH$3:$AH$523,P!$AL$3:$AL$523) -> 21.675081 | S4: =R4+LOOKUP($M4,P!$AH$3:$AH$523,P!$AM$3:$AM$523) -> 25.086296 | T4: 1.3085928 | V4: 2.0493714
A5: 51938.7 | G5: 25.672 | H5: 896.0899 | I5: -0.0819 | J5: 4.1042364 | M5: 0.3 | N5: =G5 -> 25.672 | O5: =I5*196.8504 -> -16.122048 | P5: =H5*3.28083 -> 2939.9186 | Q5: =(H5-T$1)*3.28083+5.38 -> 27.000342 | R5: =$Q5-LOOKUP($M5,P!$AH$3:$AH$523,P!$AL$3:$AL$523) -> 21.621712 | S5: =R5+LOOKUP($M5,P!$AH$3:$AH$523,P!$AM$3:$AM$523) -> 24.993067 | T5: 2.6274962 | V5: 4.1042364
A6: 51938.8 | G6: 25.873 | H6: 896.0814 | I6: -0.082 | J6: 6.1664112 | M6: 0.4 | N6: =G6 -> 25.873 | O6: =I6*196.8504 -> -16.141733 | P6: =H6*3.28083 -> 2939.8907 | Q6: =(H6-T$1)*3.28083+5.38 -> 26.972455 | R6: =$Q6-LOOKUP($M6,P!$AH$3:$AH$523,P!$AL$3:$AL$523) -> 21.56739 | S6: =R6+LOOKUP($M6,P!$AH$3:$AH$523,P!$AM$3:$AM$523) -> 24.897922 | T6: 3.9555108 | V6: 6.1664112
A7: 51938.9 | G7: 26.021 | H7: 896.0694 | I7: -0.1178 | J7: 8.2364236 | M7: 0.5 | N7: =G7 -> 26.021 | O7: =I7*196.8504 -> -23.188977 | P7: =H7*3.28083 -> 2939.8514 | Q7: =(H7-T$1)*3.28083+5.38 -> 26.933085 | R7: =$Q7-LOOKUP($M7,P!$AH$3:$AH$523,P!$AL$3:$AL$523) -> 21.521775 | S7: =R7+LOOKUP($M7,P!$AH$3:$AH$523,P!$AM$3:$AM$523) -> 24.842664 | T7: 5.2925896 | V7: 8.2364236
A8: 51939 | G8: 26.242 | H8: 896.049 | I8: -0.2019 | J8: 10.313924 | M8: 0.6 | N8: =G8 -> 26.242 | O8: =I8*196.8504 -> -39.744096 | P8: =H8*3.28083 -> 2939.7844 | Q8: =(H8-T$1)*3.28083+5.38 -> 26.866156 | R8: =$Q8-LOOKUP($M8,P!$AH$3:$AH$523,P!$AL$3:$AL$523) -> 21.452765 | S8: =R8+LOOKUP($M8,P!$AH$3:$AH$523,P!$AM$3:$AM$523) -> 24.770439 | T8: 6.641401 | V8: 10.313924
A9: 51939.1 | G9: 26.339 | H9: 896.0218 | I9: -0.2695 | J9: 12.397329 | M9: 0.7 | N9: =G9 -> 26.339 | O9: =I9*196.8504 -> -53.051183 | P9: =H9*3.28083 -> 2939.6952 | Q9: =(H9-T$1)*3.28083+5.38 -> 26.776917 | R9: =$Q9-LOOKUP($M9,P!$AH$3:$AH$523,P!$AL$3:$AL$523) -> 21.359155 | S9: =R9+LOOKUP($M9,P!$AH$3:$AH$523,P!$AM$3:$AM$523) -> 24.670079 | T9: 7.9943187 | V9: 12.397329
A10: 51939.2 | G10: 26.509 | H10: 895.9928 | I10: -0.2885 | J10: 14.487823 | M10: 0.8 | N10: =G10 -> 26.509 | O10: =I10*196.8504 -> -56.79134 | P10: =H10*3.28083 -> 2939.6001 | Q10: =(H10-T$1)*3.28083+5.38 -> 26.681773 | R10: =$Q10-LOOKUP($M10,P!$AH$3:$AH$523,P!$AL$3:$AL$523) -> 21.256309 | S10: =R10+LOOKUP($M10,P!$AH$3:$AH$523,P!$AM$3:$AM$523) -> 24.55534 | T10: 9.3558242 | V10: 14.487823
A11: 51939.3 | G11: 26.67 | H11: 895.9605 | I11: -0.3205 | J11: 16.583813 | M11: 0.9 | N11: =G11 -> 26.67 | O11: =I11*196.8504 -> -63.090553 | P11: =H11*3.28083 -> 2939.4941 | Q11: =(H11-T$1)*3.28083+5.38 -> 26.575802 | R11: =$Q11-LOOKUP($M11,P!$AH$3:$AH$523,P!$AL$3:$AL$523) -> 21.129107 | S11: =R11+LOOKUP($M11,P!$AH$3:$AH$523,P!$AM$3:$AM$523) -> 24.395351 | T11: 10.726428 | V11: 16.583813
A12: 51939.4 | G12: 26.796 | H12: 895.9276 | I12: -0.327 | J12: 18.687068 | M12: 1 | N12: =G12 -> 26.796 | O12: =I12*196.8504 -> -64.370081 | P12: =H12*3.28083 -> 2939.3861 | Q12: =(H12-T$1)*3.28083+5.38 -> 26.467863 | R12: =$Q12-LOOKUP($M12,P!$AH$3:$AH$523,P!$AL$3:$AL$523) -> 20.987448 | S12: =R12+LOOKUP($M12,P!$AH$3:$AH$523,P!$AM$3:$AM$523) -> 24.201617 | T12: 12.102668 | V12: 18.687068
A13: 51939.5 | G13: 26.958 | H13: 895.8945 | I13: -0.3299 | J13: 20.798415 | M13: 1.1 | N13: =G13 -> 26.958 | O13: =I13*196.8504 -> -64.940947 | P13: =H13*3.28083 -> 2939.2776 | Q13: =(H13-T$1)*3.28083+5.38 -> 26.359267 | R13: =$Q13-LOOKUP($M13,P!$AH$3:$AH$523,P!$AL$3:$AL$523) -> 20.85325 | S13: =R13+LOOKUP($M13,P!$AH$3:$AH$523,P!$AM$3:$AM$523) -> 24.027881 | T13: 13.487496 | V13: 20.798415
A14: 51939.6 | G14: 27.055 | H14: 895.8628 | I14: -0.3149 | J14: 22.917782 | M14: 1.2 | N14: =G14 -> 27.055 | O14: =I14*196.8504 -> -61.988191 | P14: =H14*3.28083 -> 2939.1736 | Q14: =(H14-T$1)*3.28083+5.38 -> 26.255265 | R14: =$Q14-LOOKUP($M14,P!$AH$3:$AH$523,P!$AL$3:$AL$523) -> 20.70741 | S14: =R14+LOOKUP($M14,P!$AH$3:$AH$523,P!$AM$3:$AM$523) -> 23.81743 | T14: 14.877 | V14: 22.917782
A15: 51939.7 | G15: 27.223 | H15: 895.8311 | I15: -0.3152 | J15: 25.043493 | M15: 1.3 | N15: =G15 -> 27.223 | O15: =I15*196.8504 -> -62.047246 | P15: =H15*3.28083 -> 2939.0695 | Q15: =(H15-T$1)*3.28083+5.38 -> 26.151263 | R15: =$Q15-LOOKUP($M15,P!$AH$3:$AH$523,P!$AL$3:$AL$523) -> 20.588837 | S15: =R15+LOOKUP($M15,P!$AH$3:$AH$523,P!$AM$3:$AM$523) -> 23.676356 | T15: 16.275798 | V15: 25.043493
... A302: 52008.4 | G302: 0.027 | H302: 890.1441 | I302: -0.0112 | J302: 417.18243 | M302: 30 | N302: =G302 -> 0.027 | O302: =I302*196.8504 -> -2.2047245 | P302: =H302*3.28083 -> 2920.4115 | Q302: =(H302-T$1)*3.28083+5.38 -> 7.4931826 | R302: =$Q302-LOOKUP($M302,P!$AH$3:$AH$523,P!$AL$3:$AL$523) -> 2.2779495 | S302: =R302+LOOKUP($M302,P!$AH$3:$AH$523,P!$AM$3:$AM$523) -> 5.9016404 | T302: 397.04751 | V302: 417.18243
V303: 0

Sheet Plot

Sheet Results
C2: PCM | D2: 26
C3: DGPS | D3: 10
D5: Till Touchdown | I5: Post Touchdown
B6: Colnum | C6: Parameters | D6: Max | E6: Min | F6: Engine Off | G6: Touchdown based on Roll rate | H6: Touchdown based on Nz and sink rate | I6: Max | J6: Min
C7: Time-Graph | F7: 9.31 | G7: 14.04 | H7: 14.9 | J7: 26 | K7: complete stop time
C8: AUW(kg) | D8: 2500
C9: Winds
C10: Nz(g) | D10: 2.048 | E10: 0.028
C11: DGPS Des Rate(fpm) | D11: -57.992128 | E11: -486.43702 | G11: -58.326774 | H11: -158.32678 | I11: 273.60237 | J11: -276.24017
C12: Radalt(ft) | F12: 21.375
C13: DGPS-Skid(ft) | D13: 20.676495 | E13: 1.2401382 | F13: 20.676495 | I13: 2.4265711 | J13: 0.59894144
C14: DGPS-Tail | D14: 23.748906 | E14: 2.6587104 | F14: 23.748906 | I14: 6.050262 | J14: 1.7153545
C15: NR(%) | F15: 99.813 | G15: 60.813 | H15: 55
C16: IAS (kt) | F16: 34.438 | G16: 39 | H16: 37.75
C17: GS(kt) | F17: 39.385 | G17: 44.934 | H17: 43.573
C18: Relative Speed(kt)
C19: DTHETA(%) | D19: 76.043 | E19: 41.025 | G19: 76.017 | H19: 73.634 | I19: 78.861 | J19: 0.138
C20: DBETA(%) | D20: 74.096 | E20: 37.256 | G20: 69.995 | H20: 39.577 | I20: 73.81 | J20: 3.775
C21: DALPHA(%) | D21: 86.283 | E21: 56.883 | G21: 74.956 | H21: 66.549 | I21: 75.467 | J21: 31.353
C22: DDELTA(%) | D22: 39.58 | E22: 5.575 | G22: 7.908 | H22: 10.739 | I22: 18.375 | J22: 0.753
C23: PITCH ANGLE(deg) | D23: 7.763 | E23: -6.901 | G23: 7.259 | H23: 0.522 | I23: 7.941 | J23: -0.676
C24: PITCH RATE (deg/s) | D24: 16.527 | E24: -10.478 | I24: 14.718 | J24: -20.166
C25: ROLL ANGLE(deg) | D25: 2.192 | E25: -6.707 | G25: -0.742 | H25: -0.327 | I25: -0.238 | J25: -1.622
C26: ROLL RATE(deg/s) | D26: 10.048 | E26: -12.338 | I26: 8.472 | J26: -11.584
C27: YAW RATE(deg/s) | D27: 8.368 | E27: -2.416 | I27: 3.19 | J27: -5.449
C28: TQ(%) | F28: 39.031794
C29: Heading | F29: -93.532 | G29: -86.56
C30: Distance traveled since touch down (m) | D30: 93.493008
